Workbook

Sheet SKU Summary
A1: SKU | B1: Description | C1: HTS | D1: Container No. | E1: PO No. | F1: HS
A2: 100PCSGXBSYT00001V0 | B2: CHAIR COVER | C2: 6304930010 | D2: MSDU6211947 | E2: Packing list=PL-054902 | F2: =_xlfn.XLOOKUP(A2,[1]邦达数据库!$A:$A,[1]邦达数据库!$C:$C) -> #N/A
A3: 100PCSQBHLYYT0001V0 | B3: CHAIR COVER | C3: 6304910000, 6304930010 | D3: BMOU4089214, BMOU4422599, CAIU8091272, DRYU9392353, FCIU8346047, GLDU7246065, MSNU8925183, TCNU7880515, TGHU9726809, TGHU9810798 | E3: Packing list=CZ-055904, Packing list=CZ-055905, Packing list=CZ-055906, Packing list=CZ-055907, Packing list=FR-054747, Packing list=FR-054749, Packing list=FR-054752, Packing list=PL-054770, Packing list=PL-054774, Packing list=PL-055927 | F3: =_xlfn.XLOOKUP(A3,[1]邦达数据库!$A:$A,[1]邦达数据库!$C:$C) -> 6304.91.0000
A4: 10CDM-ABSZSJ00001V0 | B4: BACKDROP STAND | C4: 8302500000 | D4: CARU5285706, FCIU8358053 | E4: Packing list=CZ-055908, Packing list=PL-055929 | F4: =_xlfn.XLOOKUP(A4,[1]邦达数据库!$A:$A,[1]邦达数据库!$C:$C) -> #N/A
A5: 10LJG-001PTJ00001V0 | B5: POWDER COATING MACHINE | C5: 7303001020 | D5: DFSU6555268, FDCU0243422, MSCU5315774 | E5: Packing list=CZ-055664, Packing list=PL-054559, Packing list=PL-055705 | F5: =_xlfn.XLOOKUP(A5,[1]邦达数据库!$A:$A,[1]邦达数据库!$C:$C) -> #N/A
A6: 10YCGDJW5730XFA8I001V0 | B6: KNEELER SEAT | C6: 8302300090 | D6: CAIU4774748 | E6: Packing list=PL-054558 | F6: =_xlfn.XLOOKUP(A6,[1]邦达数据库!$A:$A,[1]邦达数据库!$C:$C) -> #N/A
A7: 110BLMCYXYKK59JRSV9 | B7: ELECTRONIC SCALE | C7: 8423828100 | D7: MSMU5818830 | E7: Packing list=PL-054556 | F7: =_xlfn.XLOOKUP(A7,[1]邦达数据库!$A:$A,[1]邦达数据库!$C:$C) -> #N/A
A8: 12VDZYFXJSYXLIK15001V9 | B8: HYDRAULIC POWER UNIT | C8: 8412298990 | D8: CAIU7378566 | E8: Packing list=CZ-055677 | F8: =_xlfn.XLOOKUP(A8,[1]邦达数据库!$A:$A,[1]邦达数据库!$C:$C) -> #N/A
A9: 12VDZYFXJSYXU2WWW001V9 | B9: HYDRAULIC POWER UNIT | C9: 8412298990 | D9: CAIU7378566 | E9: Packing list=CZ-055677 | F9: =_xlfn.XLOOKUP(A9,[1]邦达数据库!$A:$A,[1]邦达数据库!$C:$C) -> #N/A
A10: 12VDZYSLYXCZJ3GNE001V9 | B10: HYDRAULIC POWER UNIT | C10: 8412292090 | D10: CAIU7378566 | E10: Packing list=CZ-055677 | F10: =_xlfn.XLOOKUP(A10,[1]邦达数据库!$A:$A,[1]邦达数据库!$C:$C) -> #N/A
A11: 12VDZYSLYXCZS7IY6001V9 | B11: HYDRAULIC POWER UNIT | C11: 8412292090 | D11: CAIU7378566 | E11: Packing list=CZ-055677 | F11: =_xlfn.XLOOKUP(A11,[1]邦达数据库!$A:$A,[1]邦达数据库!$C:$C) -> #N/A
A12: 12VLWTYNTJ129ROVH001C2V2 | B12: REVERSE CONTROL KIT | C12: 8504408790 | D12: CAIU7140710 | E12: Packing list=FR-055407 | F12: =_xlfn.XLOOKUP(A12,[1]邦达数据库!$A:$A,[1]邦达数据库!$C:$C) -> #N/A
A13: 12VLWTYNTJ12AKVBU001C2V2 | B13: REVERSE CONTROL KIT | C13: 8504408790 | D13: CAIU7140710 | E13: Packing list=FR-055407 | F13: =_xlfn.XLOOKUP(A13,[1]邦达数据库!$A:$A,[1]邦达数据库!$C:$C) -> #N/A
... A20: 220BLMCYXYKKMJVL1V9 | B20: ELECTRONIC SCALE | C20: 8423828100 | D20: MSMU5818830 | E20: Packing list=PL-054556 | F20: =_xlfn.XLOOKUP(A20,[1]邦达数据库!$A:$A,[1]邦达数据库!$C:$C) -> #N/A
A21: 28ZDAQZ28YC4I2SSDV0 | B21: SAFETY CONES | C21: 3926905000 | D21: MEDU7093501, TGBU4628768 | E21: Packing list=CZ-055903, Packing list=PL-054773 | F21: 6307.90.9899
A22: 2G3000WKQD0000001V2 | B22: INFRARED PAINT LAMP | C22: 8419891000 | D22: MSBU7968460 | E22: list=IT-052076 | F22: =_xlfn.XLOOKUP(A22,[1]邦达数据库!$A:$A,[1]邦达数据库!$C:$C) -> #N/A
A23: 2H1ZCCT52JT1LWFL2001V0 | B23: BEARING AND SEAL DRIVER SET | C23: 7326909210 | D23: CAAU5661620, MSDU8279268, TXGU6715988 | E23: Packing list=CZ-055655, Packing list=CZ-055660, Packing list=PL-055706 | F23: =_xlfn.XLOOKUP(A23,[1]邦达数据库!$A:$A,[1]邦达数据库!$C:$C) -> #N/A
A24: 2JTJBDCWGNWFQ1SDC001V0 | B24: HOT TUB STEP | C24: 7326903000 | D24: CAIU7733254, MSBU8246837 | E24: Packing list=CZ-056449, Packing list=PL-056510 | F24: =_xlfn.XLOOKUP(A24,[1]邦达数据库!$A:$A,[1]邦达数据库!$C:$C) -> #N/A
A25: 2TCCDGJ0000000001V0 | B25: HOISTING HOOKS | C25: 7315820000 | D25: MSDU6211947, TCLU8016320 | E25: Packing list=CZ-056026, Packing list=PL-054902 | F25: =_xlfn.XLOOKUP(A25,[1]邦达数据库!$A:$A,[1]邦达数据库!$C:$C) -> #N/A
A26: 30KGGZ00000000001V0 | B26: ANVIL | C26: 7303001010 | D26: MSMU8224934 | E26: list=FR-052059 | F26: =_xlfn.XLOOKUP(A26,[1]邦达数据库!$A:$A,[1]邦达数据库!$C:$C) -> #N/A
A27: 30YFZQWZJ8LXX4BJCV0 | B27: CARILLON | C27: 9205100000 | D27: SELU4270474 | E27: list=ES-049339 | F27: =_xlfn.XLOOKUP(A27,[1]邦达数据库!$A:$A,[1]邦达数据库!$C:$C) -> #N/A
A28: 30YFZQWZJWLXDYZRGV0 | B28: CARILLON | C28: 9205100000 | D28: FFAU2882889, MSBU7968460 | E28: list=IT-049334, list=IT-052076 | F28: =_xlfn.XLOOKUP(A28,[1]邦达数据库!$A:$A,[1]邦达数据库!$C:$C) -> #N/A
A29: 316BXGGSS150M0001V0 | B29: STEEL WIRE ROPE | C29: 7408290000 | D29: FSCU6992068, MSNU8441810, MSNU9783205 | E29: Packing list=CZ-056028, Packing list=FR-054886, Packing list=PL-054904 | F29: =_xlfn.XLOOKUP(A29,[1]邦达数据库!$A:$A,[1]邦达数据库!$C:$C) -> #N/A
A30: 316BXGGSS300M0001V0 | B30: STEEL WIRE ROPE | C30: 7408290000 | D30: FSCU6992068, MSNU8441810, MSNU9783205 | E30: Packing list=CZ-056028, Packing list=FR-054886, Packing list=PL-054904 | F30: =_xlfn.XLOOKUP(A30,[1]邦达数据库!$A:$A,[1]邦达数据库!$C:$C) -> #N/A
A31: 316GSS7X700000001V0 | B31: STEEL WIRE ROPE | C31: 7408290000 | D31: FSCU6992068, MSNU8441810, MSNU9783205 | E31: Packing list=CZ-056028, Packing list=FR-054886, Packing list=PL-054904 | F31: =_xlfn.XLOOKUP(A31,[1]邦达数据库!$A:$A,[1]邦达数据库!$C:$C) -> #N/A
A32: 32YFZQWZJWLXWXEC2V0 | B32: CARILLON | C32: 9205100000 | D32: FFAU2882889 | E32: list=IT-049334 | F32: =_xlfn.XLOOKUP(A32,[1]邦达数据库!$A:$A,[1]邦达数据库!$C:$C) -> #N/A
A33: 32YFZQYZJWLX0A1C1V0 | B33: CARILLON | C33: 9205100000 | D33: SELU4270474 | E33: list=ES-049339 | F33: =_xlfn.XLOOKUP(A33,[1]邦达数据库!$A:$A,[1]邦达数据库!$C:$C) -> #N/A
... A82: AQMANSITYPE1L9NAX001V0 | B82: HARD HAT | C82: 3926906000 | D82: MSDU8279268, TXGU6715988 | E82: Packing list=CZ-055660, Packing list=PL-055706 | F82: =_xlfn.XLOOKUP(A82,[1]邦达数据库!$A:$A,[1]邦达数据库!$C:$C) -> #N/A
A83: AQSJTZ60JDGB62SHMV0 | B83: LOCKOUT TAGOUT KIT | C83: 7323910000 | D83: MSDU8088467 | E83: Packing list=PL-054772 | F83: 8301.10.0000
A84: AQZ36X4.5INHS0001V0 | B84: SAFETY BOLLARDS | C84: 7308909890 | D84: AXIU1638505, FFAU4034300 | E84: Packing list=FR-054748, Packing list=PL-054775 | F84: =_xlfn.XLOOKUP(A84,[1]邦达数据库!$A:$A,[1]邦达数据库!$C:$C) -> 7308909890
A85: ATVGSSJP2000PXII1V9 | B85: ELECTRIC WINCH | C85: 7323910000 | D85: CAIU7575647, FDCU0243422 | E85: Packing list=CZ-055663, Packing list=PL-054559 | F85: =_xlfn.XLOOKUP(A85,[1]邦达数据库!$A:$A,[1]邦达数据库!$C:$C) -> #N/A
A86: ATVGSSJPYXWXEJRPBV9 | B86: ELECTRIC WINCH | C86: 7323910000 | D86: CAIU7575647, FDCU0243422 | E86: Packing list=CZ-055663, Packing list=PL-054559 | F86: =_xlfn.XLOOKUP(A86,[1]邦达数据库!$A:$A,[1]邦达数据库!$C:$C) -> #N/A
A87: ATVGSSJPYXYK43JX7V9 | B87: ELECTRIC WINCH | C87: 7323910000 | D87: MSMU5818830 | E87: Packing list=PL-054556 | F87: =_xlfn.XLOOKUP(A87,[1]邦达数据库!$A:$A,[1]邦达数据库!$C:$C) -> #N/A
A88: ATVHCSJPYXWXMCF1OV9 | B88: ELECTRIC WINCH | C88: 8205510000 | D88: MSDU8450658, TXGU8904131 | E88: Packing list=CZ-054518, Packing list=PL-054562 | F88: =_xlfn.XLOOKUP(A88,[1]邦达数据库!$A:$A,[1]邦达数据库!$C:$C) -> #N/A
A89: AXLSTCQJDSYKA13UA001V0 | B89: A-FRAME JACK | C89: 8425420000 | D89: MSBU8068680 | E89: Packing list=CZ-054519 | F89: =_xlfn.XLOOKUP(A89,[1]邦达数据库!$A:$A,[1]邦达数据库!$C:$C) -> #N/A
A90: AXQQTZ1RWCGHWRPSE001V0 | B90: A-FRAME SWING SET | C90: 9506999000 | D90: MEDU4464722, MSDU6211947 | E90: Packing list=FR-054884, Packing list=PL-054902 | F90: =_xlfn.XLOOKUP(A90,[1]邦达数据库!$A:$A,[1]邦达数据库!$C:$C) -> #N/A
A91: AXQQTZ2RWCGL2KT8O001V0 | B91: A-FRAME SWING SET | C91: 9506999000 | D91: MEDU4464722, MSDU6211947 | E91: Packing list=FR-054884, Packing list=PL-054902 | F91: =_xlfn.XLOOKUP(A91,[1]邦达数据库!$A:$A,[1]邦达数据库!$C:$C) -> #N/A
A92: AXQQTZSL1RW07PILCV0 | B92: A-FRAME SWING SET | C92: 7323910000 | D92: CAIU7751371, MSCU4594885 | E92: Packing list=FR-054885, Packing list=PL-054903 | F92: =_xlfn.XLOOKUP(A92,[1]邦达数据库!$A:$A,[1]邦达数据库!$C:$C) -> #N/A
A93: AZSJGMTZDDFSTV95SV0 | B93: RAISED TOILET SEAT | C93: 3922200000 | D93: MSBU8246837, MSDU5115018 | E93: Packing list=CZ-056446, Packing list=CZ-056449 | F93: =_xlfn.XLOOKUP(A93,[1]邦达数据库!$A:$A,[1]邦达数据库!$C:$C) -> #N/A
A94: AZXKZDYTXSJKFJJNV001V0 | B94: PULL UP BAR | C94: 9506919000 | D94: MSBU5511156, MSCU5315774 | E94: Packing list=CZ-055664, Packing list=PL-054560 | F94: =_xlfn.XLOOKUP(A94,[1]邦达数据库!$A:$A,[1]邦达数据库!$C:$C) -> #N/A
...
